<?xml version="1.0" encoding="utf-8"?>
<robot name="wl_description">
    <!-- ros_control plugin -->
    <gazebo>
        <plugin name="gazebo_ros_control" filename="libgazebo_ros_control.so">
            <robotNamespace>/wl_gazebo</robotNamespace>
        </plugin>
    </gazebo>
    <!-- Show the trajectory of trunk center. -->
    <gazebo>
        <plugin name="3dplot" filename="libLinkPlot3DPlugin.so">
            <frequency>10</frequency>
            <plot>
                <link>base_link</link>
                <pose>0 0 0 0 0 0</pose>
                <material>Gazebo/Yellow</material>
            </plot>
        </plugin>
    </gazebo>
    <!-- Show the effect of external force on the trunk center. -->
    <gazebo>
    <plugin filename="libgazebo_ros_force.so" name="gazebo_ros_force">
        <bodyName>base_link</bodyName>
        <topicName>/apply_force/base_link</topicName>
    </plugin>
    </gazebo>
    <!-- Show IMU plugin -->
    <gazebo reference="base_link">
        <gravity>true</gravity>
        <sensor name="imu_sensor" type="imu">
            <always_on>true</always_on>
            <update_rate>1000</update_rate>
            <visualize>true</visualize>
            <topic>__default_topic__</topic>
            <plugin filename="libgazebo_ros_imu_sensor.so" name="imu_plugin">
                <topicName>trunk_imu</topicName>
                <bodyName>base_link</bodyName>
                <updateRateHZ>1000.0</updateRateHZ>
                <gaussianNoise>0.0</gaussianNoise>
                <xyzOffset>0 0 0</xyzOffset>
                <rpyOffset>0 0 0</rpyOffset>
                <frameName>base_link</frameName>
            </plugin>
            <pose>0 0 0 0 0 0</pose>
        </sensor>
    </gazebo>

    <!-- Display the colors of each component -->
    <gazebo reference="base_link">
        <mu1>0.2</mu1>
        <mu2>0.2</mu2>
        <kp value="1000000.0"/>
        <kd value="1.0"/>
    </gazebo>

    <!-- Base Link Gazebo Configuration -->
    <gazebo reference="base_link">
        <material>Gazebo/DarkGrey</material>
        <mu1>0.2</mu1>
        <mu2>0.2</mu2>
    </gazebo>

    <!-- Front Left Lower Limb (lf0_Link) Gazebo Configuration -->
    <gazebo reference="lf0_Link">
        <material>Gazebo/DarkGrey</material>
        <mu1>0.2</mu1>
        <mu2>0.2</mu2>
    </gazebo>

    <!-- Front Left Upper Limb (lf1_Link) Gazebo Configuration -->
    <gazebo reference="lf1_Link">
        <material>Gazebo/DarkGrey</material>
        <mu1>0.2</mu1>
        <mu2>0.2</mu2>
    </gazebo>

    <!-- Left Wheel (l_wheel_Link) Gazebo Configuration -->
    <gazebo reference="l_wheel_Link">
        <material>Gazebo/DarkGrey</material>
        <mu1>0.6</mu1>
        <mu2>0.6</mu2>
    </gazebo>

    <!-- Right Front Lower Limb (rf0_Link) Gazebo Configuration -->
    <gazebo reference="rf0_Link">
        <material>Gazebo/DarkGrey</material>
        <mu1>0.2</mu1>
        <mu2>0.2</mu2>
    </gazebo>

    <!-- Right Front Upper Limb (rf1_Link) Gazebo Configuration -->
    <gazebo reference="rf1_Link">
        <material>Gazebo/DarkGrey</material>
        <mu1>0.2</mu1>
        <mu2>0.2</mu2>
    </gazebo>

    <!-- Right Wheel (r_wheel_Link) Gazebo Configuration -->
    <gazebo reference="r_wheel_Link">
        <material>Gazebo/DarkGrey</material>
        <mu1>0.6</mu1>
        <mu2>0.6</mu2>
    </gazebo>

    <!-- 固定机器人在空中 -->
    <!-- <link name="world" />

    <joint name="base_to_world" type="fixed">
        <parent link="world"/>
        <child link="base_link"/>
        <origin xyz="0 0 0.3" rpy="0 0 0"/> 
    </joint> -->

    <!-- Base Link -->
    <link name="base_link">
        <inertial>
            <origin xyz="-0.0076 0.0067 0.123056" rpy="0 0 0" />
            <mass value="8.8" />
            <inertia ixx="0.326092" ixy="3.6E-05" ixz="-0.00115" iyy="0.229526" iyz="0.006798" izz="0.220537" />
        </inertial>
        <visual>
            <origin xyz="0 0 0" rpy="0 0 0" />
            <geometry>
                <mesh filename="package://wl_description/meshes/base_link.STL" />
            </geometry>
            <material name="">
                <color rgba="0.79216 0.81961 0.93333 1" />
            </material>
        </visual>
        <collision>
            <origin xyz="0 0 0" rpy="0 0 0" />
            <geometry>
                <mesh filename="package://wl_description/meshes/base_link.STL" />
            </geometry>
        </collision>
    </link>
    <link name="lf0_Link">
        <inertial>
            <origin xyz="0.05976637 -0.00048182 0.01198236" rpy="0 0 0" />
            <mass value="0.16" />
            <inertia ixx="0.00006424" ixy="0.00000030" ixz="0.00012472" iyy="0.00116066" iyz="-0.00000101" izz="0.00117029" />
        </inertial>
        <visual>
            <origin xyz="0 0 0" rpy="0 0 0" />
            <geometry>
                <mesh filename="package://wl_description/meshes/lf0_Link.STL" />
            </geometry>
            <material name="">
                <color rgba="0.792156862745098 0.819607843137255 0.933333333333333 1" />
            </material>
        </visual>
        <collision>
            <origin xyz="0 0 0" rpy="0 0 0" />
            <geometry>
                <mesh filename="package://wl_description/meshes/lf0_Link.STL" />
            </geometry>
        </collision>
    </link>
    <joint name="lf0_Joint" type="revolute">
        <origin xyz="0.054 0.1705 0.131" rpy="-1.5708 0 0" />
        <parent link="base_link" />
        <child link="lf0_Link" />
        <axis xyz="0 0 1" />
        <dynamics damping="0" friction="0"/>
        <limit lower="-0.3363" upper="1.3479" effort="30" velocity="1000" />
    </joint>
    <link name="lf1_Link">
        <inertial>
            <origin xyz="-0.00032544 0.15899848 0.00798168" rpy="0 0 0" />
            <mass value="0.36" />
            <inertia ixx="0.01248770" ixy="-0.00000383" ixz="-0.00000106" iyy="0.00011869" iyz="0.00042404" izz="0.01251325" />
        </inertial>
        <visual>
            <origin xyz="0 0 0" rpy="0 0 0" />
            <geometry>
                <mesh filename="package://wl_description/meshes/lf1_Link.STL" />
            </geometry>
            <material name="">
                <color rgba="0.792156862745098 0.819607843137255 0.933333333333333 1" />
            </material>
        </visual>
        <collision>
            <origin xyz="0 0 0" rpy="0 0 0" />
            <geometry>
                <mesh filename="package://wl_description/meshes/lf1_Link.STL" />
            </geometry>
        </collision>
    </link>
    <joint name="lf1_Joint" type="revolute">
        <origin xyz="0.15 -0.00010199 0.0205" rpy="0 0 0" />
        <parent link="lf0_Link" />
        <child link="lf1_Link" />
        <axis xyz="0 0 1" />
        <dynamics damping="0" friction="0"/>
        <limit lower="-1.0" upper="1.25" effort="30" velocity="1000" />
    </joint>
    <link name="l_wheel_Link">
        <inertial>
            <origin xyz="-0.00004507 -0.00038447 0.02376028" rpy="0 0 0" />
            <mass value="1.22" />
            <inertia ixx="0.00174370" ixy="-0.00000195" ixz="-0.00000028" iyy="0.00176013" iyz="-0.00000241" izz="0.00173973" />
        </inertial>
        <visual>
            <origin xyz="0 0 0" rpy="0 0 0" />
            <geometry>
                <mesh filename="package://wl_description/meshes/l_wheel_Link.STL" />
            </geometry>
            <material name="">
                <color rgba="0.792156862745098 0.819607843137255 0.933333333333333 1" />
            </material>
        </visual>
        <collision>
            <origin xyz="0 0 0.03" rpy="0 0 0" />
            <geometry>
                <cylinder length="0.025" radius="0.0675"/>
            </geometry>
        </collision>
    </link>
    <!-- <joint name="l_wheel_Joint" type="revolute"> -->
    <joint name="l_wheel_Joint" type="continuous">
        <origin xyz="1.857E-05 0.25 0.0275" rpy="0 0 0" />
        <parent link="lf1_Link" />
        <child link="l_wheel_Link" />
        <axis xyz="0 0 1" />
        <dynamics damping="0" friction="0"/>
        <limit effort="5" velocity="1000" />
        <!-- <limit lower="-100000000000000000000000000000.25" upper="10000000000000000000000000.0" effort="5" velocity="1000" /> -->
    </joint>
    <link name="rf0_Link">
        <inertial>
            <origin xyz="0.05976637 -0.00048182 0.01198236" rpy="0 0 0" />
            <mass value="0.16" />
            <inertia ixx="0.00006424" ixy="0.00000174" ixz="0.00012472" iyy="0.00116066" iyz="-0.00000084" izz="0.00117029" />
        </inertial>
        <visual>
            <origin xyz="0 0 0" rpy="0 0 0" />
            <geometry>
                <mesh filename="package://wl_description/meshes/rf0_Link.STL" />
            </geometry>
            <material name="">
                <color rgba="0.792156862745098 0.819607843137255 0.933333333333333 1" />
            </material>
        </visual>
        <collision>
            <origin xyz="0 0 0" rpy="0 0 0" />
            <geometry>
                <mesh filename="package://wl_description/meshes/rf0_Link.STL" />
            </geometry>
        </collision>
    </link>
    <joint name="rf0_Joint" type="revolute">
        <origin xyz="0.054 -0.1705 0.131" rpy="1.5708 0 0" />
        <parent link="base_link" />
        <child link="rf0_Link" />
        <axis xyz="0 0 1" />
        <dynamics damping="0" friction="0"/>
        <limit lower="-1.3479" upper="0.3363" effort="30" velocity="1000" />
    </joint>
    <link name="rf1_Link">
        <inertial>
            <origin xyz="0.00032544 -0.15899848 0.00798168" rpy="0 0 0" />
            <mass value="0.36" />
            <inertia ixx="0.01248770" ixy="-0.00000553" ixz="0.00000112" iyy="0.00011869" iyz="-0.00042404" izz="0.01251325" />
        </inertial>
        <visual>
            <origin xyz="0 0 0" rpy="0 0 0" />
            <geometry>
                <mesh filename="package://wl_description/meshes/rf1_Link.STL" />
            </geometry>
            <material name="">
                <color rgba="0.792156862745098 0.819607843137255 0.933333333333333 1" />
            </material>
        </visual>
        <collision>
            <origin xyz="0 0 0" rpy="0 0 0" />
            <geometry>
                <mesh filename="package://wl_description/meshes/rf1_Link.STL" />
            </geometry>
        </collision>
    </link>
    <joint name="rf1_Joint" type="revolute">
        <origin xyz="0.15 9.5536E-05 0.0205" rpy="0 0 0" />
        <parent link="rf0_Link" />
        <child link="rf1_Link" />
        <axis xyz="0 0 1" />
        <dynamics damping="0" friction="0"/>
        <limit lower="-1.25" upper="1.0" effort="30" velocity="1000" />
    </joint>
    <link name="r_wheel_Link">
        <inertial>
            <origin xyz="0.00038403 0.00004865 0.02376028" rpy="0 0 0" />
            <mass value="1.22" />
            <inertia ixx="0.00176009" ixy="-0.00000211" ixz="0.00000241" iyy="0.00174374" iyz="0.00000031" izz="0.00173973" />
        </inertial>
        <visual>
            <origin xyz="0 0 0" rpy="0 0 0" />
            <geometry>
                <mesh filename="package://wl_description/meshes/r_wheel_Link.STL" />
            </geometry>
            <material name="">
                <color rgba="0.792156862745098 0.819607843137255 0.933333333333333 1" />
            </material>
        </visual>
        <collision>
            <origin xyz="0 0 0.03" rpy="0 0 0" />
            <geometry>
                <cylinder length="0.025" radius="0.0675"/>
            </geometry>
        </collision>
    </link>
    <!-- <joint name="r_wheel_Joint" type="revolute"> -->
    <joint name="r_wheel_Joint" type="continuous">
        <origin xyz="1.5909E-05 -0.25 0.0275" rpy="0 0 0" />
        <parent link="rf1_Link" />
        <child link="r_wheel_Link" />
        <axis xyz="0 0 1" />
        <dynamics damping="0" friction="0"/>
        <!-- <limit lower="-100000000000000000000000000000.25" upper="10000000000000000000000000.0" effort="5" velocity="1000" /> -->
        <limit effort="5" velocity="1000" />
    </joint>
    <!-- ############################################################ -->
    <transmission name="lf0_Joint_tran">
        <type>transmission_interface/SimpleTransmission</type>
        <joint name="lf0_Joint">
        <hardwareInterface>hardware_interface/EffortJointInterface</hardwareInterface>
        </joint>
        <actuator name="lf0_Joint_motor">
        <hardwareInterface>hardware_interface/EffortJointInterface</hardwareInterface>
        <mechanicalReduction>1</mechanicalReduction>
        </actuator>
    </transmission>
    <transmission name="lf1_Joint_tran">
        <type>transmission_interface/SimpleTransmission</type>
        <joint name="lf1_Joint">
        <hardwareInterface>hardware_interface/EffortJointInterface</hardwareInterface>
        </joint>
        <actuator name="lf1_Joint_motor">
        <hardwareInterface>hardware_interface/EffortJointInterface</hardwareInterface>
        <mechanicalReduction>1</mechanicalReduction>
        </actuator>
    </transmission>
    <transmission name="l_wheel_Joint_tran">
        <type>transmission_interface/SimpleTransmission</type>
        <joint name="l_wheel_Joint">
        <hardwareInterface>hardware_interface/EffortJointInterface</hardwareInterface>
        </joint>
        <actuator name="l_wheel_Joint_motor">
        <hardwareInterface>hardware_interface/EffortJointInterface</hardwareInterface>
        <mechanicalReduction>1</mechanicalReduction>
        </actuator>
    </transmission>
    <transmission name="rf0_Joint_tran">
        <type>transmission_interface/SimpleTransmission</type>
        <joint name="rf0_Joint">
        <hardwareInterface>hardware_interface/EffortJointInterface</hardwareInterface>
        </joint>
        <actuator name="rf0_Joint_motor">
        <hardwareInterface>hardware_interface/EffortJointInterface</hardwareInterface>
        <mechanicalReduction>1</mechanicalReduction>
        </actuator>
    </transmission>
    <transmission name="rf1_Joint_tran">
        <type>transmission_interface/SimpleTransmission</type>
        <joint name="rf1_Joint">
        <hardwareInterface>hardware_interface/EffortJointInterface</hardwareInterface>
        </joint>
        <actuator name="rf1_Joint_motor">
        <hardwareInterface>hardware_interface/EffortJointInterface</hardwareInterface>
        <mechanicalReduction>1</mechanicalReduction>
        </actuator>
    </transmission>
    <transmission name="r_wheel_Joint_tran">
        <type>transmission_interface/SimpleTransmission</type>
        <joint name="r_wheel_Joint">
        <hardwareInterface>hardware_interface/EffortJointInterface</hardwareInterface>
        </joint>
        <actuator name="r_wheel_Joint_motor">
        <hardwareInterface>hardware_interface/EffortJointInterface</hardwareInterface>
        <mechanicalReduction>1</mechanicalReduction>
        </actuator>
    </transmission>
</robot>
